[TOC]

1、异常的产生以及对于程序的影响；

2、异常的处理格式；

3、异常的处理流程；

4、throw、throws 关键字的使用；

5、异常处理的使用标准；

6、自定义异常。

# 一、异常的产生

​	异常是导致程序中断执行的一种指令流，异常一旦出现并且没有进行合理处理的话，那么程序就将中断。

​	一旦产生异常之后，产生异常的语句以及之后的语句将不再执行，默认情况下是进行异常信息的输出而后结束程序的执行。我们要做的事情是：即使出现了一次，那么也应该让程序正确的执行完毕。

# 二、处理异常

如果要进行异常的处理， Java 提供了三个关键字： try、catch、throw。

try{

// 要处理异常的程序

}[catch(异常类型 对象){

​	//异常处理

}catch(异常类型 对象){

​	//异常处理

}catch(异常类型 对象){

​	//异常处理

}…][finally{

// 不管是否出现异常，都执行的统一代码

}]

对于以上的各种组合：try...catch、try...catch...finally、try...finally。

范例：应用异常处理格式

```java
public class TestDemo{
	public static void main(String args[]){
		System.out.println("1、除法计算开始");
		try{
			System.out.println("2、除法计算" + 10 / 0);
			System.out.println("*****************");
		}catch(ArithmeticException e){
			System.out.println("***出现异常***");
		}		
		System.out.println("3、除法计算结束");
	}
}
```

​	由于使用了异常处理，这样即使程序中出现了异常，也可以正常的执行完毕。出现异常的目的是为了解决异常，所以为了能进行异常的处理，可以使用异常类提供的 printStackTrace() 方法进行异常信息的完整输出。

```java
public class TestDemo{
	public static void main(String args[]){
		System.out.println("1、除法计算开始");
		try{
			System.out.println("2、除法计算" + 10 / 0);
			System.out.println("*****************");
		}catch(ArithmeticException e){
			e.printStackTrace();
		}		
		System.out.println("3、除法计算结束");
	}
}
```

​	此时发现打印的异常信息是很完整的。

范例：还可以使用 try…catch…finally

```java
public class TestDemo{
	public static void main(String args[]){
		System.out.println("1、除法计算开始");
		try{
			System.out.println("2、除法计算" + 10 / 0);
			System.out.println("*****************");
		}catch(ArithmeticException e){
			e.printStackTrace();
		}finally{
			System.out.println("不管出现异常我都执行");
		}		
		System.out.println("3、除法计算结束");
	}
}
```

​	在异常捕获的时候发现一个 try 语句后可以有多个 catch 语句。

```java
public class TestDemo{
	public static void main(String args[]){
		int x = Integer.parseInt(args[0]);
		int y = Integer.parseInt(args[1]);
		System.out.println("1、除法计算开始");
		try{
			System.out.println("2、除法计算" + x / y);
			System.out.println("*****************");
		}catch(ArithmeticException e){
			e.printStackTrace();
		}finally{
			System.out.println("不管出现异常我都执行");
		}		
		System.out.println("3、除法计算结束");
	}
}
```

以上的程序将由用户输入操作数据，于是可能出现有如下的情况：

- 用户执行的时候不输入参数(java Exception)：java.lang.ArrayIndexOutOfBoundsException，未处理；
- 用户输入的参数不是数字（java Exception a b）：java.lang.NumberFormatException，没有处理；
- 被除数为0（java Exception 10 0）：java.lang.ArithmeticException，已处理。

以上的代码只有一个 catch，所以只能处理一个异常，如果其它没有处理的异常，依然会导致程序中断执行。

范例：加入多个 catch。

```java
public class TestDemo{
	public static void main(String args[]){
		System.out.println("1、除法计算开始");
		try{
			int x = Integer.parseInt(args[0]);
			int y = Integer.parseInt(args[1]);
			System.out.println("2、除法计算" + x / y);
			System.out.println("*****************");
		}catch(ArithmeticException e){
			e.printStackTrace();
		}catch(ArrayIndexOutOfBoundsException e){
			e.printStackTrace();
		}catch(NumberFormatException e){
			e.printStackTrace();
		}finally{
			System.out.println("不管出现异常我都执行");
		}		
		System.out.println("3、除法计算结束");
	}
}
```

​	程序现在的确很健壮，所有可能出现的异常都处理完了。以上的异常都已经知道了，你还让它出现，这绝对是技术问题。

# 三、异常的处理流程（核心）

​	通过以上的分析已经掌握了异常的处理格式了，但是遗憾的是以上的操作并不是最佳的处理方式，所以必须要清楚整个 Java 中异常的处理流程。首先来观察两个异常类的继承结构：

| ArithmeticException                      |          NumberFormatException           |
| :--------------------------------------- | :--------------------------------------: |
| [java.lang.Object](https://docs.oracle.com/javase/8/docs/api/java/lang/Object.html)    [java.lang.Throwable](https://docs.oracle.com/javase/8/docs/api/java/lang/Throwable.html)    [java.lang.Exception](https://docs.oracle.com/javase/8/docs/api/java/lang/Exception.html)    [java.lang.RuntimeException](https://docs.oracle.com/javase/8/docs/api/java/lang/RuntimeException.html)    java.lang.ArithmeticException | [java.lang.Object](https://docs.oracle.com/javase/8/docs/api/java/lang/Object.html)    [java.lang.Throwable](https://docs.oracle.com/javase/8/docs/api/java/lang/Throwable.html)    [java.lang.Exception](https://docs.oracle.com/javase/8/docs/api/java/lang/Exception.html)    [java.lang.RuntimeException](https://docs.oracle.com/javase/8/docs/api/java/lang/RuntimeException.html)    [java.lang.IllegalArgumentException](https://docs.oracle.com/javase/8/docs/api/java/lang/IllegalArgumentException.html)    java.lang.NumberFormatException |

​	经过异常类的观察可以发现：所有的异常类都是 Throwable 的子类。而在 Throwable 下有两个子类： Error 和 Exception 。

面试题：请解释 Error 和 Exception 的区别？

- Error ：指的是 JVM 错误，即此时的程序还没有执行，如果没有执行用户无法处理；
- Exception ：指的是程序运行中产生的异常，用户可以处理。

也就是所谓的异常处理指的是 所有 Exception 以及它的子类异常。

面试题：请解释 Java 中异常的处理流程：

![pic1](/Users/chenjinhua/git/javaLearning/[20]异常的捕获及处理/pic1.png)

1、当程序在运行过程中出现了异常， 会由 JVM 自动根据异常的类型实例化一个与之类型匹配的异常类对象（此处用户不用关心 new ，由系统自动负责处理）；

2、产生了异常对象之后，会判断是否有异常处理，如果现在没有异常处理，那么就交给 JVM 进行默认的异常处理：输出异常信息，然后结束程序的调用；

3、如果此时存在有异常的捕获操作，那么会由 try 语句来捕获产生的异常类实例化对象，然后与try 语句后的每一个 catch 进行比较，如果有符合的捕获类型，则使用对应的catch 语句来进行异常的处理，如果不匹配则向下继续匹配其他的 catch；

4、不管最后异常处理是否能匹配，那么都要向后执行，如果此时程序中存在 finally 语句，那么就执行 finally里的代码，但是执行完毕后需要根据之前的catch 匹配结果来决定如何执行，如果之前已经成功的捕获了异常，那么就继续执行 finally 之后的代码，如果之前没有成功的捕获异常，那么就将此异常交给 JVM进行默认的异常处理。

​	整个过程就好比方法重载一样。根据 catch 后面的参数类型进行匹配，但是 Java 中存在对象的自动向上转型，也就是说如果要真的匹配类型，简单的做法是匹配 Exception 类型就可以了。

范例：使用 Exception 处理异常

```java
public class TestDemo{
	public static void main(String args[]){
		System.out.println("1、除法计算开始");
		try{
			int x = Integer.parseInt(args[0]);
			int y = Integer.parseInt(args[1]);
			System.out.println("2、除法计算" + x / y);
			System.out.println("*****************");
		}catch(Exception e){
			e.printStackTrace();
		}finally{
			System.out.println("不管出现异常我都执行");
		}		
		System.out.println("3、除法计算结束");
	}
}	
```

此时所有的异常都使用了 Exception 进行处理，所以在程序中不用再去关心具体的异常。

**两点说明**

- 在编写捕获异常的时候，捕获范围大的异常一定要放在捕获范围小的异常之后，否则程序编译错误；
- 虽然直接捕获 Exception 比较方便，但是这样也不好，因为所有的异常都会按照同样一种方式进行处理，如果在一些要求严格的项目里，异常分开处理会更好。

# 四、 throws 关键字

​	throws 关键字主要用于方法声明，指的是当方法中出现异常后交由被调用处进行处理。

范例：使用 throws

```java
class Math{
	// 由于存在有 throws，表示此方法里面产生的异常由被调用处进行处理
	public staitc int div(int x,int y) throws Exception{
		return x/y;
	}
}
```

范例：被调用处进行处理

```java
class MyMath{
	// 由于存在有 throws，表示此方法里面产生的异常由被调用处进行处理
	public staitc int div(int x,int y) throws Exception{
		return x/y;
	}
}
public class TestDemo{
	public static void main(String args[]){
		try{
			System.out.println(MyMath.div(10,2));
		}
		catch(Exception e){
			e.printStackTrace();
		}
}
```

​	也就是说：使用 throws 声明的方法之后，不管操作是否出现异常，都必须使用 try … catch 进行异常的处理。

​	可是在程序中，主方法也属于方法，那么主方法上是否可以使用 throws 声明呢？

```java
class MyMath{
	// 由于存在有 throws，表示此方法里面产生的异常由被调用处进行处理
	public staitc int div(int x,int y) throws Exception{
		return x/y;
	}
}
public class TestDemo{
	public static void main(String args[]) throws Exception{
		// 表示此异常产生之后会直接通过主方法抛出
		System.out.println(MyMath.div(10,0));
    }
}
```

​	在主方法上如果抛出了异常，那么就将交给 JVM 进行处理，也就是采用默认的处理方式：输出异常信息，按行结束程序调用。很明显，我们不应该在主方法上加 throws。因为程序如果出错了，我们也希望程序运行完成。

# 五、 throw 关键字

在程序中可以直接使用 throw 手工的抛出一个异常类的实例化对象。

范例：手工抛一个异常

```java
public class TestDemo{
	public static void main(String args[]){
		try{
			throw new Exception("自己定义的异常！");
		}catch(Exception e){
			e.printStackTrace();
		}
	}
}
```

​	异常肯定应该尽量回避，没事非要自己再抛个异常。

面试题： throw 和 throws 的区别？

- throw ：在方法中人为抛出一个异常类对象（这个异常类对象可以是自己实例化或者是抛出已存在的）；
- throws：在方法的声明上使用，表示此方法在调用时必须处理异常。

# 六、重要的代码模型：异常处理的标准格式

​	需求：定义一个 div()，该方法在进行计算之前打印提示信息，在计算结束完毕也打印提示信息，如果在计算中产生了一次，则交给被调用处进行处理。

范例：首先给出代码不出错的情况

```java
class MyMath{
	public static int div(int x, int y){
		int result = 0;
		System.out.println("1、除法计算开始");
		result = x/y;
		System.out.println("2、除法计算结束");
		return result;
	}
}
public class TestDemo{
	public static void main(String args[]){
		System.out.println(MyMath.div(10,2));
	}
}
```

​	对于以上给出的除法操作不可能永远都正常完成，所以应该进行一些合理的处理，首先如果说某一个方法出现异常了，必须交给被调用处处理，那么应该在方法上使用 throws 抛出。

```java
class MyMath{
	public static int div(int x, int y) throws Exception{
		int result = 0;
		System.out.println("1、除法计算开始");
		result = x/y;
		System.out.println("2、除法计算结束");
		return result;
	}
}
public class TestDemo{
	public static void main(String args[]){
		try{
			System.out.println(MyMath.div(10,2));
		}catch(Exception e){
			e.printStackTrace();
		}
	}
}
```

​	可是当以上的代码真的出错时，程序有些内容就不执行了，这明显不对。

```java
class MyMath{
	public static int div(int x, int y) throws Exception{
		int result = 0;
		System.out.println("1、除法计算开始");
		try{
			result = x/y;
		}catch(Exception e){
			throw e;  // 继续抛异常
		}finally{
			System.out.println("2、除法计算结束");
		}
		return result;
	}
}
public class TestDemo{
	public static void main(String args[]){
		try{
			System.out.println(MyMath.div(10,0));
		}catch(Exception e){
			e.printStackTrace();
		}finally{}
	}
}
```

​	实际上以上的代码还可以缩写。

```java
class MyMath{
	public static int div(int x, int y) throws Exception{
		int result = 0;
		System.out.println("1、除法计算开始");
		try{
			result = x/y;
		}finally{
			System.out.println("2、除法计算结束");
		}
		return result;
	}
}
public class TestDemo{
	public static void main(String args[]){
		try{
			System.out.println(MyMath.div(10,0));
		}catch(Exception e){
			e.printStackTrace();
		}finally{}
	}
}
```

​	不过不建议用上面的方法，如果直接使用 try…finally，那么表示你连处理一下的机会都没有就直接抛出了。

#七、RuntimeException 类

首先观察一个程序代码：

```java
public class TestDemo{
	public static void main(String args[]){
		// 将字符串变成 整数
		int temp = Integer.parseInt("100");
	}
}
```

现在来观察一下 parseInt() 方法定义

```java
public static int parseInt(String s)
                    throws NumberFormatException
```

此时 parseInt() 抛出了 NumberFormatException，按道理应该该方法被调用时要处理这种异常，但是这里并没有强制性的要求，来观察一下 NumberFormatException 的继承结构。

```java
   java.lang.Object    
   java.lang.Throwable    
   java.lang.Exception    
   java.lang.RuntimeException    // 运行时异常
   java.lang.IllegalArgumentException    
   java.lang.NumberFormatException
```

​	在 Java 里为了方便用户代码的编写，专门提供了一种 RuntimeException 类，这种类的最大特征在于：程序在编译时，不会强制性的要求用户处理异常，用户可以根据自己的需要选择性的进行处理，但是如果没有处理又发生异常了将交给 JVM 默认处理。也就是说 RuntimeException 的子异常类可以由用户根据需要选择进行处理。

面试题：请解释 Exception 与 RuntimeException 的区别？请列举出几个常见的 RuntimeException。

- Exception 是 RuntimeException 的父类；
- 使用 Exception 定义的异常必须要被处理，而 RuntimeException 的异常可以选择性处理。
- 常见的RuntimeException：ClassCastException、NullPointerException、ArithmeticException。

# 八、assert 关键字（了解）

Assert 关键字是在 JDK 1.4 后引入的，其主要的功能是进行断言。

在 Java 中的断言，指的是程序执行到某行代码处时一定是预期的结果。

范例：观察断言

```java
public class TestDemo{
	public static void main(String args[]){
		int num = 10;
		// 中间可能经过了20行代码来操作num的内容
		// 期望中num 内容应该是20
		assert num = 20: "num 的内容不是20";
		System.out.println("num = " + num);
	}
}
```

​	默认情况断言是不影响程序的运行的，也就是说在 java 解释程序的时候，断言是默认不起作用的。

启用断言：java -ea Exception。使用的意义也不大。

# 九、自定义异常

​	Java 本身提供了大量的异常，但是在实际工作中往往并不够使用。例如，当要执行数据增加操作时，有可能会出现错误的数据，而这些错误的数据出现时就应该抛出异常，例如：AddException，但是这样的异常 Java 并没有，所以就需要用户自己去开发一个自己的异常类。

​	如果要开发自己自定义的异常类可以选择继承 Exception 或者是 RuntimeException。

```java
class AddException extends Exception{
	public AddException(String msg){
		super(msg);
	}
}
public class TestDemo{
	public static void main(String args[]){
		int num = 20;
		try{
			if(num >10){
				throw new AddException(" 传递的数值过大 ");
			}
		}catch(Exception e){
			e.printStackTrace();
		}
	}
}
```

​	这种代码只能是介绍自定义异常的形式，但是并不能说明自定义异常的使用。

# 十、总结

1、Exception 的父类是 Throwable，但是在编写代码的时候尽量不要使用 Throwable，因为 Throwable 还拥有一个 Error 子类，我们能够处理的只有 Exception 子类；

**2、异常处理的标准格式：try、catch、finally、throws、throw；**

3、RuntimeException 和 Exception 的区别（前者是有选择性的处理，后者是强制。）